Some weights of the model checkpoint at microsoft/deberta-v3-large were not used when initializing DebertaV2Model: ['mask_predictions.LayerNorm.weight', 'mask_predictions.classifier.weight', 'mask_predictions.classifier.bias', 'lm_predictions.lm_head.dense.weight', 'mask_predictions.LayerNorm.bias', 'lm_predictions.lm_head.LayerNorm.weight', 'mask_predictions.dense.bias', 'mask_predictions.dense.weight', 'lm_predictions.lm_head.bias', 'lm_predictions.lm_head.dense.bias', 'lm_predictions.lm_head.LayerNorm.bias']
- This IS expected if you are initializing DebertaV2Model from the checkpoint of a model trained on another task or with another architecture (e.g. initializing a BertForSequenceClassification model from a BertForPreTraining model).
- This IS NOT expected if you are initializing DebertaV2Model from the checkpoint of a model that you expect to be exactly identical (initializing a BertForSequenceClassification model from a BertForSequenceClassification model).
[1/20] Train & Validation
/home/qcqced/anaconda3/lib/python3.9/site-packages/transformers/optimization.py:306: FutureWarning: This implementation of AdamW is deprecated and will be removed in a future version. Use the PyTorch implementation torch.optim.AdamW instead, or set `no_deprecation_warning=True` to disable this warning
  warnings.warn(
  grad_norm = torch.nn.utils.clip_grad_norm(                                                                                    | 0/42 [00:00<?, ?it/s]
  File "/home/qcqced/anaconda3/lib/python3.9/site-packages/torch/autograd/function.py", line 274, in apply              | 1/42 [00:10<06:59, 10.23s/it]
    return user_fn(self, *args)
  File "/home/qcqced/anaconda3/lib/python3.9/site-packages/torch/utils/checkpoint.py", line 141, in backward
    outputs = ctx.run_function(*detached_inputs)
  File "/home/qcqced/anaconda3/lib/python3.9/site-packages/transformers/models/deberta_v2/modeling_deberta_v2.py", line 529, in custom_forward
    return module(*inputs, output_attentions)
  File "/home/qcqced/anaconda3/lib/python3.9/site-packages/torch/nn/modules/module.py", line 1501, in _call_impl
    return forward_call(*args, **kwargs)
  File "/home/qcqced/anaconda3/lib/python3.9/site-packages/transformers/models/deberta_v2/modeling_deberta_v2.py", line 386, in forward
    attention_output = self.attention(
  File "/home/qcqced/anaconda3/lib/python3.9/site-packages/torch/nn/modules/module.py", line 1501, in _call_impl
    return forward_call(*args, **kwargs)
  File "/home/qcqced/anaconda3/lib/python3.9/site-packages/transformers/models/deberta_v2/modeling_deberta_v2.py", line 317, in forward
    self_output = self.self(
  File "/home/qcqced/anaconda3/lib/python3.9/site-packages/torch/nn/modules/module.py", line 1501, in _call_impl
    return forward_call(*args, **kwargs)
  File "/home/qcqced/anaconda3/lib/python3.9/site-packages/transformers/models/deberta_v2/modeling_deberta_v2.py", line 761, in forward
    attention_probs = self.dropout(attention_probs)
  File "/home/qcqced/anaconda3/lib/python3.9/site-packages/torch/nn/modules/module.py", line 1501, in _call_impl
    return forward_call(*args, **kwargs)
  File "/home/qcqced/anaconda3/lib/python3.9/site-packages/transformers/models/deberta_v2/modeling_deberta_v2.py", line 258, in forward
    return XDropout.apply(x, self.get_context())
  File "/home/qcqced/anaconda3/lib/python3.9/site-packages/torch/autograd/function.py", line 506, in apply
    return super().apply(*args, **kwargs)  # type: ignore[misc]
 (Triggered internally at /opt/conda/conda-bld/pytorch_1678402412426/work/torch/csrc/autograd/python_anomaly_mode.cpp:114.)
  Variable._execution_engine.run_backward(  # Calls into the C++ engine to run the backward pass
/home/qcqced/anaconda3/lib/python3.9/site-packages/torch/autograd/__init__.py:200: UserWarning:
Previous calculation was induced by CheckpointFunctionBackward. Traceback of forward call that induced the previous calculation:
  File "/home/qcqced/바탕화면/ML_Test/UPPPM/train.py", line 51, in <module>
    main('upppm_config.json', CFG)
  File "/home/qcqced/바탕화면/ML_Test/UPPPM/train.py", line 32, in main
    getattr(train_loop, cfg.loop)(cfg)  # init object
  File "/home/qcqced/바탕화면/ML_Test/UPPPM/trainer/train_loop.py", line 41, in train_loop
    train_loss, grad_norm, lr = train_input.train_fn(
  File "/home/qcqced/바탕화면/ML_Test/UPPPM/trainer/trainer.py", line 117, in train_fn
    preds = model(inputs)
  File "/home/qcqced/anaconda3/lib/python3.9/site-packages/torch/nn/modules/module.py", line 1501, in _call_impl
    return forward_call(*args, **kwargs)
  File "/home/qcqced/바탕화면/ML_Test/UPPPM/model/model.py", line 51, in forward
    outputs = self.feature(inputs)
  File "/home/qcqced/바탕화면/ML_Test/UPPPM/model/model.py", line 47, in feature
    outputs = self.model(**inputs)
  File "/home/qcqced/anaconda3/lib/python3.9/site-packages/torch/nn/modules/module.py", line 1501, in _call_impl
    return forward_call(*args, **kwargs)
  File "/home/qcqced/anaconda3/lib/python3.9/site-packages/transformers/models/deberta_v2/modeling_deberta_v2.py", line 1099, in forward
    encoder_outputs = self.encoder(
  File "/home/qcqced/anaconda3/lib/python3.9/site-packages/torch/nn/modules/module.py", line 1501, in _call_impl
    return forward_call(*args, **kwargs)
  File "/home/qcqced/anaconda3/lib/python3.9/site-packages/transformers/models/deberta_v2/modeling_deberta_v2.py", line 533, in forward
    output_states = torch.utils.checkpoint.checkpoint(
  File "/home/qcqced/anaconda3/lib/python3.9/site-packages/torch/utils/checkpoint.py", line 249, in checkpoint
    return CheckpointFunction.apply(function, preserve, *args)
  File "/home/qcqced/anaconda3/lib/python3.9/site-packages/torch/autograd/function.py", line 506, in apply
    return super().apply(*args, **kwargs)  # type: ignore[misc]
 (Triggered internally at /opt/conda/conda-bld/pytorch_1678402412426/work/torch/csrc/autograd/python_anomaly_mode.cpp:121.)
  Variable._execution_engine.run_backward(  # Calls into the C++ engine to run the backward pass
/home/qcqced/anaconda3/lib/python3.9/site-packages/torch/autograd/__init__.py:200: UserWarning: Error detected in CheckpointFunctionBackward. Traceback of forward call that caused the error:
  File "/home/qcqced/바탕화면/ML_Test/UPPPM/train.py", line 51, in <module>
    main('upppm_config.json', CFG)
  File "/home/qcqced/바탕화면/ML_Test/UPPPM/train.py", line 32, in main
    getattr(train_loop, cfg.loop)(cfg)  # init object
  File "/home/qcqced/바탕화면/ML_Test/UPPPM/trainer/train_loop.py", line 41, in train_loop
    train_loss, grad_norm, lr = train_input.train_fn(
  File "/home/qcqced/바탕화면/ML_Test/UPPPM/trainer/trainer.py", line 117, in train_fn
    preds = model(inputs)
  File "/home/qcqced/anaconda3/lib/python3.9/site-packages/torch/nn/modules/module.py", line 1501, in _call_impl
    return forward_call(*args, **kwargs)
  File "/home/qcqced/바탕화면/ML_Test/UPPPM/model/model.py", line 51, in forward
    outputs = self.feature(inputs)
  File "/home/qcqced/바탕화면/ML_Test/UPPPM/model/model.py", line 47, in feature
    outputs = self.model(**inputs)
  File "/home/qcqced/anaconda3/lib/python3.9/site-packages/torch/nn/modules/module.py", line 1501, in _call_impl
    return forward_call(*args, **kwargs)
  File "/home/qcqced/anaconda3/lib/python3.9/site-packages/transformers/models/deberta_v2/modeling_deberta_v2.py", line 1099, in forward
    encoder_outputs = self.encoder(
  File "/home/qcqced/anaconda3/lib/python3.9/site-packages/torch/nn/modules/module.py", line 1501, in _call_impl
    return forward_call(*args, **kwargs)
  File "/home/qcqced/anaconda3/lib/python3.9/site-packages/transformers/models/deberta_v2/modeling_deberta_v2.py", line 533, in forward
    output_states = torch.utils.checkpoint.checkpoint(
  File "/home/qcqced/anaconda3/lib/python3.9/site-packages/torch/utils/checkpoint.py", line 249, in checkpoint
    return CheckpointFunction.apply(function, preserve, *args)
  File "/home/qcqced/anaconda3/lib/python3.9/site-packages/torch/autograd/function.py", line 506, in apply
    return super().apply(*args, **kwargs)  # type: ignore[misc]
 (Triggered internally at /opt/conda/conda-bld/pytorch_1678402412426/work/torch/csrc/autograd/python_anomaly_mode.cpp:114.)
  Variable._execution_engine.run_backward(  # Calls into the C++ engine to run the backward pass
  2%|██▋                                                                                                                | 1/42 [00:13<08:54, 13.04s/it]
Traceback (most recent call last):
  File "/home/qcqced/바탕화면/ML_Test/UPPPM/train.py", line 51, in <module>
    main('upppm_config.json', CFG)
  File "/home/qcqced/바탕화면/ML_Test/UPPPM/train.py", line 32, in main
    getattr(train_loop, cfg.loop)(cfg)  # init object
  File "/home/qcqced/바탕화면/ML_Test/UPPPM/trainer/train_loop.py", line 41, in train_loop
    train_loss, grad_norm, lr = train_input.train_fn(
  File "/home/qcqced/바탕화면/ML_Test/UPPPM/trainer/trainer.py", line 126, in train_fn
    scaler.scale(loss).backward()
  File "/home/qcqced/anaconda3/lib/python3.9/site-packages/torch/_tensor.py", line 487, in backward
    torch.autograd.backward(
  File "/home/qcqced/anaconda3/lib/python3.9/site-packages/torch/autograd/__init__.py", line 200, in backward
    Variable._execution_engine.run_backward(  # Calls into the C++ engine to run the backward pass
  File "/home/qcqced/anaconda3/lib/python3.9/site-packages/torch/autograd/function.py", line 274, in apply
    return user_fn(self, *args)
  File "/home/qcqced/anaconda3/lib/python3.9/site-packages/torch/utils/checkpoint.py", line 157, in backward
    torch.autograd.backward(outputs_with_grad, args_with_grad)
  File "/home/qcqced/anaconda3/lib/python3.9/site-packages/torch/autograd/__init__.py", line 200, in backward
    Variable._execution_engine.run_backward(  # Calls into the C++ engine to run the backward pass
  File "/home/qcqced/anaconda3/lib/python3.9/site-packages/torch/autograd/function.py", line 274, in apply
    return user_fn(self, *args)
  File "/home/qcqced/anaconda3/lib/python3.9/site-packages/transformers/models/deberta_v2/modeling_deberta_v2.py", line 213, in backward
    return grad_output.masked_fill(mask, 0) * ctx.scale, None
torch.cuda.OutOfMemoryError: CUDA out of memory. Tried to allocate 2.00 GiB (GPU 0; 23.69 GiB total capacity; 17.92 GiB already allocated; 1.20 GiB free; 21.26 GiB reserved in total by PyTorch) If reserved memory is >> allocated memory try setting max_split_size_mb to avoid fragmentation.  See documentation for Memory Management and PYTORCH_CUDA_ALLOC_CONF